<sdf version='1.9'>
  <model name='leo_sim'>
    <link name='base_footprint'>
      <inertial>
        <pose>-0.01965072201211552 0.01167759118438614 0.1660702125213793 0 0 0</pose>
        <mass>1.5862309999999999</mass>
        <inertia>
          <ixx>0.01042630889712674</ixx>
          <ixy>0.001176207094533427</ixy>
          <ixz>-0.00088806760314957389</ixz>
          <iyy>0.01045413545998981</iyy>
          <iyz>0.00021963222424937429</iyz>
          <izz>0.018172704009346379</izz>
        </inertia>
      </inertial>
      <collision name='base_footprint_fixed_joint_lump__base_collision_collision'>
        <pose>0 0 0.14783 0 0 0</pose>
        <geometry>
          <box>
            <size>0.35 0.25 0.12</size>
          </box>
        </geometry>
      </collision>
      <visual name='base_footprint_fixed_joint_lump__base_link_visual'>
        <pose>0 0 0.19783 0 0 0</pose>
        <geometry>
          <mesh>
            <scale>1 1 1</scale>
            <uri>model://leo_description/models/Chassis.dae</uri>
          </mesh>
        </geometry>
        <material>
          <diffuse>1 0 0 1</diffuse>
          <ambient>1 0 0 1</ambient>
        </material>
      </visual>
      <visual name='base_footprint_fixed_joint_lump__antenna_link_visual_1'>
        <pose>-0.0052 0.056 0.19133 0 0 0</pose>
        <geometry>
          <mesh>
            <scale>1 1 1</scale>
            <uri>model://leo_description/models/Antenna.dae</uri>
          </mesh>
        </geometry>
      </visual>
      <visual name='base_footprint_fixed_joint_lump__realsense_link_visual_2'>
        <pose>0.1 0 0.22783 0 -0.3000000000000001 0</pose>
        <geometry>
          <mesh>
            <scale>1 1 1</scale>
            <uri>model://leo_description/models/d435.dae</uri>
          </mesh>
        </geometry>
      </visual>
      <sensor name='depth_camera' type='rgbd_camera'>
        <always_on>true</always_on>
        <update_rate>5</update_rate>
        <camera name='depth_camera'>
          <horizontal_fov>1.51844</horizontal_fov>
          <lens>
            <intrinsics>
              <fx>554.25468999999998</fx>
              <fy>554.25468999999998</fy>
              <cx>320.5</cx>
              <cy>240.5</cy>
              <s>0</s>
            </intrinsics>
            <type>stereographic</type>
            <scale_to_hfov>true</scale_to_hfov>
          </lens>
          <distortion>
            <k1>0</k1>
            <k2>0</k2>
            <k3>0</k3>
            <p1>0</p1>
            <p2>0</p2>
            <center>0.5 0.5</center>
          </distortion>
          <image>
            <width>64</width>
            <height>48</height>
            <format>R8G8B8</format>
          </image>
          <clip>
            <near>0.01</near>
            <far>300</far>
          </clip>
          <depth_camera>
            <clip>
              <near>0.10000000000000001</near>
              <far>10</far>
            </clip>
            <output>depths</output>
          </depth_camera>
          <noise>
            <type>gaussian</type>
            <mean>0</mean>
            <stddev>0.0070000000000000001</stddev>
          </noise>
        </camera>
        <topic>depth_camera</topic>
        <pose>0.1 0 0.22783 0 -0.3 0</pose>
      </sensor>
      <sensor name="robot_contact" type="contact">
    <always_on>true</always_on>
    <update_rate>50</update_rate>
    <contact>
      <collision>base_footprint_fixed_joint_lump__base_collision_collision</collision>
    </contact>
    <visualize>true</visualize>
    <topic>/robot_0/contact</topic> <!-- optional but helpful -->
  </sensor>
    </link>
    <joint name='rocker_L_joint' type='revolute'>
      <pose relative_to='base_footprint'>0.00263 0.14167 0.15052 0 0 3.141592653589793</pose>
      <parent>base_footprint</parent>
      <child>rocker_L_link</child>
      <axis>
        <xyz>0 1 0</xyz>
        <limit>
          <lower>-0.23999999999999999</lower>
          <upper>0.23999999999999999</upper>
          <effort>100</effort>
          <velocity>100</velocity>
        </limit>
        <dynamics>
          <damping>0.10000000000000001</damping>
          <friction>1</friction>
          <spring_reference>0</spring_reference>
          <spring_stiffness>0</spring_stiffness>
        </dynamics>
      </axis>
    </joint>
    <link name='rocker_L_link'>
      <pose relative_to='rocker_L_joint'>0 0 0 0 0 0</pose>
      <inertial>
        <pose>0 0.01346 -0.06506000000000001 0 0 0</pose>
        <mass>1.3873359999999999</mass>
        <inertia>
          <ixx>0.0029559999999999999</ixx>
          <ixy>-1.4893239999999999e-06</ixy>
          <ixz>-8.1034070000000002e-06</ixz>
          <iyy>0.029239999999999999</iyy>
          <iyz>7.1119999999999997e-05</iyz>
          <izz>0.028320000000000001</izz>
        </inertia>
      </inertial>
      <collision name='rocker_L_link_collision'>
        <pose>0 0 -0.05 0 0 0</pose>
        <geometry>
          <box>
            <size>0.25 0.05 0.05</size>
          </box>
        </geometry>
        <surface>
          <friction>
            <ode>
              <mu>0.29999999999999999</mu>
              <mu2>0.29999999999999999</mu2>
            </ode>
            <bullet>
              <friction>0.29999999999999999</friction>
              <friction2>0.29999999999999999</friction2>
              <rolling_friction>0.10000000000000001</rolling_friction>
            </bullet>
          </friction>
          <contact>
            <ode/>
          </contact>
        </surface>
      </collision>
      <visual name='rocker_L_link_visual'>
        <pose>0 0 0 0 0 0</pose>
        <geometry>
          <mesh>
            <scale>1 1 1</scale>
            <uri>model://leo_description/models/Rocker.dae</uri>
          </mesh>
        </geometry>
      </visual>
    </link>
    <joint name='wheel_FL_joint' type='revolute'>
      <pose relative_to='rocker_L_link'>-0.15256 -0.08214 -0.08802 0 0 0</pose>
      <parent>rocker_L_link</parent>
      <child>wheel_FL_link</child>
      <axis>
        <xyz>0 -1 0</xyz>
        <limit>
          <effort>2</effort>
          <velocity>6</velocity>
          <lower>-10000000000000000</lower>
          <upper>10000000000000000</upper>
        </limit>
        <dynamics>
          <damping>0.10000000000000001</damping>
          <friction>0.3125</friction>
          <spring_reference>0</spring_reference>
          <spring_stiffness>0</spring_stiffness>
        </dynamics>
      </axis>
    </joint>
    <link name='wheel_FL_link'>
      <pose relative_to='wheel_FL_joint'>0 0 0 0 0 0</pose>
      <inertial>
        <pose>0 0.030026 0 0 0 0</pose>
        <mass>0.28364200000000001</mass>
        <inertia>
          <ixx>0.00039100000000000002</ixx>
          <ixy>1.2396200000000001e-06</ixy>
          <ixz>5.5258200000000004e-07</ixz>
          <iyy>0.00047160000000000002</iyy>
          <iyz>-2.082042e-06</iyz>
          <izz>0.00039100000000000002</izz>
        </inertia>
      </inertial>
      <collision name='wheel_FL_link_collision'>
        <pose>0 0.04485 0 1.570796326794896 0 0</pose>
        <geometry>
          <cylinder>
            <length>0.040000000000000001</length>
            <radius>0.0625</radius>
          </cylinder>
        </geometry>
        <surface>
          <friction>
            <ode>
              <mu>1</mu>
              <mu2>1</mu2>
              <slip1>0.035000000000000003</slip1>
              <slip2>0</slip2>
              <fdir1>0 0 1</fdir1>
            </ode>
            <bullet>
              <friction>1</friction>
              <friction2>1</friction2>
              <rolling_friction>0.10000000000000001</rolling_friction>
            </bullet>
          </friction>
          <contact>
            <ode/>
          </contact>
        </surface>
      </collision>
      <visual name='wheel_FL_link_visual'>
        <pose>0 0 0 0 0 0</pose>
        <geometry>
          <mesh>
            <scale>1 1 1</scale>
            <uri>model://leo_description/models/WheelA.dae</uri>
          </mesh>
        </geometry>
      </visual>
    </link>
    <joint name='wheel_RL_joint' type='revolute'>
      <pose relative_to='rocker_L_link'>0.15256 -0.08214 -0.08802 0 0 0</pose>
      <parent>rocker_L_link</parent>
      <child>wheel_RL_link</child>
      <axis>
        <xyz>0 -1 0</xyz>
        <limit>
          <effort>2</effort>
          <velocity>6</velocity>
          <lower>-10000000000000000</lower>
          <upper>10000000000000000</upper>
        </limit>
        <dynamics>
          <damping>0.10000000000000001</damping>
          <friction>0.3125</friction>
          <spring_reference>0</spring_reference>
          <spring_stiffness>0</spring_stiffness>
        </dynamics>
      </axis>
    </joint>
    <link name='wheel_RL_link'>
      <pose relative_to='wheel_RL_joint'>0 0 0 0 0 0</pose>
      <inertial>
        <pose>0 0.030026 0 0 0 0</pose>
        <mass>0.28364200000000001</mass>
        <inertia>
          <ixx>0.00039100000000000002</ixx>
          <ixy>1.2396200000000001e-06</ixy>
          <ixz>5.5258200000000004e-07</ixz>
          <iyy>0.00047160000000000002</iyy>
          <iyz>-2.082042e-06</iyz>
          <izz>0.00039100000000000002</izz>
        </inertia>
      </inertial>
      <collision name='wheel_RL_link_collision'>
        <pose>0 0.04485 0 1.570796326794896 0 0</pose>
        <geometry>
          <cylinder>
            <length>0.040000000000000001</length>
            <radius>0.0625</radius>
          </cylinder>
        </geometry>
        <surface>
          <friction>
            <ode>
              <mu>1</mu>
              <mu2>1</mu2>
              <slip1>0.035000000000000003</slip1>
              <slip2>0</slip2>
              <fdir1>0 0 1</fdir1>
            </ode>
            <bullet>
              <friction>1</friction>
              <friction2>1</friction2>
              <rolling_friction>0.10000000000000001</rolling_friction>
            </bullet>
          </friction>
          <contact>
            <ode/>
          </contact>
        </surface>
      </collision>
      <visual name='wheel_RL_link_visual'>
        <pose>0 0 0 0 0 0</pose>
        <geometry>
          <mesh>
            <scale>1 1 1</scale>
            <uri>model://leo_description/models/WheelA.dae</uri>
          </mesh>
        </geometry>
      </visual>
    </link>
    <joint name='rocker_R_joint' type='revolute'>
      <pose relative_to='base_footprint'>0.00263 -0.14167 0.15052 0 0 0</pose>
      <parent>base_footprint</parent>
      <child>rocker_R_link</child>
      <axis>
        <xyz>0 1 0</xyz>
        <limit>
          <lower>-0.23999999999999999</lower>
          <upper>0.23999999999999999</upper>
          <effort>100</effort>
          <velocity>100</velocity>
        </limit>
        <dynamics>
          <damping>0.10000000000000001</damping>
          <friction>1</friction>
          <spring_reference>0</spring_reference>
          <spring_stiffness>0</spring_stiffness>
        </dynamics>
      </axis>
    </joint>
    <link name='rocker_R_link'>
      <pose relative_to='rocker_R_joint'>0 0 0 0 0 0</pose>
      <inertial>
        <pose>0 0.01346 -0.06506000000000001 0 0 0</pose>
        <mass>1.3873359999999999</mass>
        <inertia>
          <ixx>0.0029559999999999999</ixx>
          <ixy>-1.4893239999999999e-06</ixy>
          <ixz>-8.1034070000000002e-06</ixz>
          <iyy>0.029239999999999999</iyy>
          <iyz>7.1119999999999997e-05</iyz>
          <izz>0.028320000000000001</izz>
        </inertia>
      </inertial>
      <collision name='rocker_R_link_collision'>
        <pose>0 0 -0.05 0 0 0</pose>
        <geometry>
          <box>
            <size>0.25 0.05 0.05</size>
          </box>
        </geometry>
        <surface>
          <friction>
            <ode>
              <mu>0.29999999999999999</mu>
              <mu2>0.29999999999999999</mu2>
            </ode>
            <bullet>
              <friction>0.29999999999999999</friction>
              <friction2>0.29999999999999999</friction2>
              <rolling_friction>0.10000000000000001</rolling_friction>
            </bullet>
          </friction>
          <contact>
            <ode/>
          </contact>
        </surface>
      </collision>
      <visual name='rocker_R_link_visual'>
        <pose>0 0 0 0 0 0</pose>
        <geometry>
          <mesh>
            <scale>1 1 1</scale>
            <uri>model://leo_description/models/Rocker.dae</uri>
          </mesh>
        </geometry>
      </visual>
    </link>
    <joint name='wheel_FR_joint' type='revolute'>
      <pose relative_to='rocker_R_link'>0.15256 -0.08214 -0.08802 0 0 0</pose>
      <parent>rocker_R_link</parent>
      <child>wheel_FR_link</child>
      <axis>
        <xyz>0 1 0</xyz>
        <limit>
          <effort>2</effort>
          <velocity>6</velocity>
          <lower>-10000000000000000</lower>
          <upper>10000000000000000</upper>
        </limit>
        <dynamics>
          <damping>0.10000000000000001</damping>
          <friction>0.3125</friction>
          <spring_reference>0</spring_reference>
          <spring_stiffness>0</spring_stiffness>
        </dynamics>
      </axis>
    </joint>
    <link name='wheel_FR_link'>
      <pose relative_to='wheel_FR_joint'>0 0 0 0 0 0</pose>
      <inertial>
        <pose>0 0.030026 0 0 0 0</pose>
        <mass>0.28364200000000001</mass>
        <inertia>
          <ixx>0.00039100000000000002</ixx>
          <ixy>1.2396200000000001e-06</ixy>
          <ixz>5.5258200000000004e-07</ixz>
          <iyy>0.00047160000000000002</iyy>
          <iyz>-2.082042e-06</iyz>
          <izz>0.00039100000000000002</izz>
        </inertia>
      </inertial>
      <collision name='wheel_FR_link_collision'>
        <pose>0 0.04485 0 1.570796326794896 0 0</pose>
        <geometry>
          <cylinder>
            <length>0.040000000000000001</length>
            <radius>0.0625</radius>
          </cylinder>
        </geometry>
        <surface>
          <friction>
            <ode>
              <mu>1</mu>
              <mu2>1</mu2>
              <slip1>0.035000000000000003</slip1>
              <slip2>0</slip2>
              <fdir1>0 0 1</fdir1>
            </ode>
            <bullet>
              <friction>1</friction>
              <friction2>1</friction2>
              <rolling_friction>0.10000000000000001</rolling_friction>
            </bullet>
          </friction>
          <contact>
            <ode/>
          </contact>
        </surface>
      </collision>
      <visual name='wheel_FR_link_visual'>
        <pose>0 0 0 0 0 0</pose>
        <geometry>
          <mesh>
            <scale>1 1 1</scale>
            <uri>model://leo_description/models/WheelB.dae</uri>
          </mesh>
        </geometry>
      </visual>
    </link>
    <joint name='wheel_RR_joint' type='revolute'>
      <pose relative_to='rocker_R_link'>-0.15256 -0.08214 -0.08802 0 0 0</pose>
      <parent>rocker_R_link</parent>
      <child>wheel_RR_link</child>
      <axis>
        <xyz>0 1 0</xyz>
        <limit>
          <effort>2</effort>
          <velocity>6</velocity>
          <lower>-10000000000000000</lower>
          <upper>10000000000000000</upper>
        </limit>
        <dynamics>
          <damping>0.10000000000000001</damping>
          <friction>0.3125</friction>
          <spring_reference>0</spring_reference>
          <spring_stiffness>0</spring_stiffness>
        </dynamics>
      </axis>
    </joint>
    <link name='wheel_RR_link'>
      <pose relative_to='wheel_RR_joint'>0 0 0 0 0 0</pose>
      <inertial>
        <pose>0 0.030026 0 0 0 0</pose>
        <mass>0.28364200000000001</mass>
        <inertia>
          <ixx>0.00039100000000000002</ixx>
          <ixy>1.2396200000000001e-06</ixy>
          <ixz>5.5258200000000004e-07</ixz>
          <iyy>0.00047160000000000002</iyy>
          <iyz>-2.082042e-06</iyz>
          <izz>0.00039100000000000002</izz>
        </inertia>
      </inertial>
      <collision name='wheel_RR_link_collision'>
        <pose>0 0.04485 0 1.570796326794896 0 0</pose>
        <geometry>
          <cylinder>
            <length>0.040000000000000001</length>
            <radius>0.0625</radius>
          </cylinder>
        </geometry>
        <surface>
          <friction>
            <ode>
              <mu>1</mu>
              <mu2>1</mu2>
              <slip1>0.035000000000000003</slip1>
              <slip2>0</slip2>
              <fdir1>0 0 1</fdir1>
            </ode>
            <bullet>
              <friction>1</friction>
              <friction2>1</friction2>
              <rolling_friction>0.10000000000000001</rolling_friction>
            </bullet>
          </friction>
          <contact>
            <ode/>
          </contact>
        </surface>
      </collision>
      <visual name='wheel_RR_link_visual'>
        <pose>0 0 0 0 0 0</pose>
        <geometry>
          <mesh>
            <scale>1 1 1</scale>
            <uri>model://leo_description/models/WheelB.dae</uri>
          </mesh>
        </geometry>
      </visual>
    </link>
    <plugin name='leo_gz::DifferentialSystem' filename='libleo_gz_differential_plugin.so'>
      <jointA>rocker_L_joint</jointA>
      <jointB>rocker_R_joint</jointB>
      <forceConstant>100.0</forceConstant>
    </plugin>
    <plugin name='gz::sim::systems::JointStatePublisher' filename='libignition-gazebo-joint-state-publisher-system.so'>
      <topic>joint_states</topic>
    </plugin>
    <plugin name='gz::sim::systems::DiffDrive' filename='libgz-sim-diff-drive-system.so'>
      <left_joint>wheel_FL_joint</left_joint>
      <right_joint>wheel_FR_joint</right_joint>
      <left_joint>wheel_RL_joint</left_joint>
      <right_joint>wheel_RR_joint</right_joint>
      <wheel_separation>0.358</wheel_separation>
      <wheel_radius>0.0625</wheel_radius>
      <frame_id>odom</frame_id>
      <child_frame_id>base_footprint</child_frame_id>
      <odom_publish_frequency>20</odom_publish_frequency>
      <topic>cmd_vel</topic>
      <odom_topic>odom</odom_topic>
      <tf_topic>tf</tf_topic>
      <max_linear_acceleration>2.5</max_linear_acceleration>
      <max_angular_acceleration>3</max_angular_acceleration>
      <min_linear_acceleration>-2.5</min_linear_acceleration>
      <min_angular_acceleration>-3</min_angular_acceleration>
    </plugin>
    <frame name='antenna_joint' attached_to='base_link'>
      <pose>-0.0052 0.056 -0.0065 0 -0 0</pose>
    </frame>
    <frame name='antenna_link' attached_to='antenna_joint'/>
    <frame name='realsense_joint' attached_to='base_link'>
      <pose>0.1 0 0.03 0 -0.3 0</pose>
    </frame>
    <frame name='realsense_link' attached_to='realsense_joint'/>
    <frame name='base_joint' attached_to='base_footprint'>
      <pose>0 0 0.19783 0 -0 0</pose>
    </frame>
    <frame name='base_link' attached_to='base_joint'/>
  </model>
</sdf>
