<?xml version="1.0" ?>
<!-- =================================================================================== -->
<!-- |    This document was autogenerated by xacro from leo.urdf.xacro                 | -->
<!-- |    EDITING THIS FILE BY HAND IS NOT RECOMMENDED                                 | -->
<!-- =================================================================================== -->
<robot name="leo">
  <!-- LEO GAZEBO -->
  <link name="base_footprint"/>
  <link name="base_link">
    <inertial>
      <mass value="1.584994"/>
      <origin xyz="-0.019662 0.011643 -0.031802"/>
      <inertia ixx="0.01042" ixy="0.001177" ixz="-0.0008871" iyy="0.01045" iyz="0.0002226" izz="0.01817"/>
    </inertial>
    <visual>
      <geometry>
        <mesh filename="package://leo_description/models/Chassis.dae"/>
      </geometry>
      <material name="_chassis_mat">
        <color rgba="1.0 0.0 0.0 1"/>
      </material>
    </visual>
    <!-- <collision>
        <geometry>
          <mesh filename="package://leo_description/models/Chassis_outline.stl"/>
        </geometry>
      </collision> -->
    <collision name="base_collision">
      <origin xyz="0 0 -0.05"/>
      <geometry>
        <box size="0.5 0.45 0.25"/>
      </geometry>
    </collision>
  </link>
  <link name="rocker_L_link">
    <inertial>
      <mass value="1.387336"/>
      <origin xyz="0 0.01346 -0.06506"/>
      <inertia ixx="0.002956" ixy="-0.000001489324" ixz="-0.000008103407" iyy="0.02924" iyz="0.00007112" izz="0.02832"/>
    </inertial>
    <visual>
      <geometry>
        <mesh filename="package://leo_description/models/Rocker.dae"/>
      </geometry>
    </visual>
    <!-- <collision>
          <geometry>
            <mesh filename="package://leo_description/models/Rocker_outline.stl"/>
          </geometry>
        </collision> -->
    <collision>
      <origin xyz="0 0 -0.05"/>
      <geometry>
        <box size="0.25 0.05 0.05"/>
      </geometry>
    </collision>
  </link>
  <link name="rocker_R_link">
    <inertial>
      <mass value="1.387336"/>
      <origin xyz="0 0.01346 -0.06506"/>
      <inertia ixx="0.002956" ixy="-0.000001489324" ixz="-0.000008103407" iyy="0.02924" iyz="0.00007112" izz="0.02832"/>
    </inertial>
    <visual>
      <geometry>
        <mesh filename="package://leo_description/models/Rocker.dae"/>
      </geometry>
    </visual>
    <!-- <collision>
          <geometry>
            <mesh filename="package://leo_description/models/Rocker_outline.stl"/>
          </geometry>
        </collision> -->
    <collision>
      <origin xyz="0 0 -0.05"/>
      <geometry>
        <box size="0.25 0.05 0.05"/>
      </geometry>
    </collision>
  </link>
  <link name="wheel_FL_link">
    <inertial>
      <mass value="0.283642"/>
      <origin xyz="0 0.030026 0"/>
      <inertia ixx="0.000391" ixy="0.00000123962" ixz="5.52582e-7" iyy="0.0004716" iyz="-0.000002082042" izz="0.000391"/>
    </inertial>
    <visual>
      <geometry>
        <mesh filename="package://leo_description/models/WheelA.dae"/>
      </geometry>
    </visual>
    <!-- <collision>
          <origin xyz="0 0.04485 0" rpy="${pi/2} 0 0"/>
          <geometry>
            <cylinder radius="0.057" length="0.07"/>
          </geometry>
        </collision> -->
    <collision>
      <origin rpy="1.5707963267948966 0 0" xyz="0 0.04485 0"/>
      <geometry>
        <cylinder length="0.04" radius="0.0625"/>
      </geometry>
    </collision>
    <!-- <collision>
          <geometry>
            <mesh filename="package://leo_description/models/Wheel_outline.stl"/>
          </geometry>
        </collision> -->
  </link>
  <link name="wheel_RL_link">
    <inertial>
      <mass value="0.283642"/>
      <origin xyz="0 0.030026 0"/>
      <inertia ixx="0.000391" ixy="0.00000123962" ixz="5.52582e-7" iyy="0.0004716" iyz="-0.000002082042" izz="0.000391"/>
    </inertial>
    <visual>
      <geometry>
        <mesh filename="package://leo_description/models/WheelA.dae"/>
      </geometry>
    </visual>
    <!-- <collision>
          <origin xyz="0 0.04485 0" rpy="${pi/2} 0 0"/>
          <geometry>
            <cylinder radius="0.057" length="0.07"/>
          </geometry>
        </collision> -->
    <collision>
      <origin rpy="1.5707963267948966 0 0" xyz="0 0.04485 0"/>
      <geometry>
        <cylinder length="0.04" radius="0.0625"/>
      </geometry>
    </collision>
    <!-- <collision>
          <geometry>
            <mesh filename="package://leo_description/models/Wheel_outline.stl"/>
          </geometry>
        </collision> -->
  </link>
  <link name="wheel_FR_link">
    <inertial>
      <mass value="0.283642"/>
      <origin xyz="0 0.030026 0"/>
      <inertia ixx="0.000391" ixy="0.00000123962" ixz="5.52582e-7" iyy="0.0004716" iyz="-0.000002082042" izz="0.000391"/>
    </inertial>
    <visual>
      <geometry>
        <mesh filename="package://leo_description/models/WheelB.dae"/>
      </geometry>
    </visual>
    <!-- <collision>
          <origin xyz="0 0.04485 0" rpy="${pi/2} 0 0"/>
          <geometry>
            <cylinder radius="0.057" length="0.07"/>
          </geometry>
        </collision> -->
    <collision>
      <origin rpy="1.5707963267948966 0 0" xyz="0 0.04485 0"/>
      <geometry>
        <cylinder length="0.04" radius="0.0625"/>
      </geometry>
    </collision>
    <!-- <collision>
          <geometry>
            <mesh filename="package://leo_description/models/Wheel_outline.stl"/>
          </geometry>
        </collision> -->
  </link>
  <link name="wheel_RR_link">
    <inertial>
      <mass value="0.283642"/>
      <origin xyz="0 0.030026 0"/>
      <inertia ixx="0.000391" ixy="0.00000123962" ixz="5.52582e-7" iyy="0.0004716" iyz="-0.000002082042" izz="0.000391"/>
    </inertial>
    <visual>
      <geometry>
        <mesh filename="package://leo_description/models/WheelB.dae"/>
      </geometry>
    </visual>
    <!-- <collision>
          <origin xyz="0 0.04485 0" rpy="${pi/2} 0 0"/>
          <geometry>
            <cylinder radius="0.057" length="0.07"/>
          </geometry>
        </collision> -->
    <collision>
      <origin rpy="1.5707963267948966 0 0" xyz="0 0.04485 0"/>
      <geometry>
        <cylinder length="0.04" radius="0.0625"/>
      </geometry>
    </collision>
    <!-- <collision>
          <geometry>
            <mesh filename="package://leo_description/models/Wheel_outline.stl"/>
          </geometry>
        </collision> -->
  </link>
  <link name="antenna_link">
    <inertial>
      <mass value="0.001237"/>
      <origin xyz="0 0 0.028828"/>
      <inertia ixx="2.5529e-7" ixy="0.0" ixz="0.0" iyy="2.5529e-7" iyz="0.0" izz="1.354e-8"/>
    </inertial>
    <visual>
      <geometry>
        <mesh filename="package://leo_description/models/Antenna.dae"/>
      </geometry>
    </visual>
  </link>
  <!-- REALSENSE CAMERA LINK -->
  <link name="realsense_link">
    <visual>
      <geometry>
        <mesh filename="package://leo_description/models/d435.dae"/>
      </geometry>
    </visual>
  </link>
  <joint name="base_joint" type="fixed">
    <origin rpy="0 0 0" xyz="0 0 0.19783"/>
    <parent link="base_footprint"/>
    <child link="base_link"/>
  </joint>
  <joint name="rocker_L_joint" type="fixed">
    <origin rpy="0 0 3.141592653589793" xyz="0.00263 0.14167 -0.04731"/>
    <parent link="base_link"/>
    <child link="rocker_L_link"/>
    <axis xyz="0 1 0"/>
    <limit effort="100.0" lower="-0.24" upper="0.24" velocity="100.0"/>
    <dynamics damping="0.1" friction="1.0"/>
  </joint>
  <joint name="rocker_R_joint" type="fixed">
    <origin rpy="0 0 0" xyz="0.00263 -0.14167 -0.04731"/>
    <parent link="base_link"/>
    <child link="rocker_R_link"/>
    <axis xyz="0 1 0"/>
    <limit effort="100.0" lower="-0.24" upper="0.24" velocity="100.0"/>
    <dynamics damping="0.1" friction="1.0"/>
    <mimic joint="rocker_L_joint"/>
  </joint>
  <joint name="wheel_FL_joint" type="continuous">
    <origin rpy="0 0 0" xyz="-0.15256 -0.08214 -0.08802"/>
    <parent link="rocker_L_link"/>
    <child link="wheel_FL_link"/>
    <axis xyz="0 -1 0"/>
    <limit effort="2.0" velocity="6.0"/>
    <dynamics damping="0.1" friction="0.3125"/>
  </joint>
  <joint name="wheel_RL_joint" type="continuous">
    <origin rpy="0 0 0" xyz="0.15256 -0.08214 -0.08802"/>
    <parent link="rocker_L_link"/>
    <child link="wheel_RL_link"/>
    <axis xyz="0 -1 0"/>
    <limit effort="2.0" velocity="6.0"/>
    <dynamics damping="0.1" friction="0.3125"/>
  </joint>
  <joint name="wheel_FR_joint" type="continuous">
    <origin rpy="0 0 0" xyz="0.15256 -0.08214 -0.08802"/>
    <parent link="rocker_R_link"/>
    <child link="wheel_FR_link"/>
    <axis xyz="0 1 0"/>
    <limit effort="2.0" velocity="6.0"/>
    <dynamics damping="0.1" friction="0.3125"/>
  </joint>
  <joint name="wheel_RR_joint" type="continuous">
    <origin rpy="0 0 0" xyz="-0.15256 -0.08214 -0.08802"/>
    <parent link="rocker_R_link"/>
    <child link="wheel_RR_link"/>
    <axis xyz="0 1 0"/>
    <limit effort="2.0" velocity="6.0"/>
    <dynamics damping="0.1" friction="0.3125"/>
  </joint>
  <joint name="antenna_joint" type="fixed">
    <origin rpy="0 0 0" xyz="-0.0052 0.056 -0.0065"/>
    <parent link="base_link"/>
    <child link="antenna_link"/>
  </joint>
  <joint name="realsense_joint" type="fixed">
    <parent link="base_link"/>
    <child link="realsense_link"/>
    <origin rpy="0 -0.3 0" xyz="0.1 0 0.03"/>
  </joint>
</robot>
